<?xml version="1.0" encoding="utf-8"?>
<!-- This URDF was automatically created by SolidWorks to URDF Exporter! Originally created by Stephen Brawner (brawner@gmail.com) 
     Commit Version: 1.6.0-4-g7f85cfe  Build Version: 1.6.7995.38578
     For more information, please see http://wiki.ros.org/sw_urdf_exporter -->
<robot
  name="simple_model_for_urdf.SLDASM">
  <link
    name="base_link">
    <inertial>
      <origin xyz="-0.15979 0.0032587 0.016482" rpy="0 0 0"/>
      <mass value="5233.5858073096"/>
      <inertia
        ixx="3681.44"
        ixy="6.68"
        ixz="721.33"
        iyy="5027.00"
        iyz="-14.23"
        izz="6024.86"/>
    </inertial>
    <visual>
      <origin
        xyz="0 0 0"
        rpy="0 0 0" />
      <geometry>
        <mesh
          filename="package://forestry_robot_mjcf/asset/base_link.STL" />
      </geometry>
      <material
        name="">
        <color
          rgba="0.65098 0.61961 0.58824 1" />
      </material>
    </visual>
    <collision>
      <origin
        xyz="0 0 0"
        rpy="0 0 0" />
      <geometry>
        <mesh
          filename="package://forestry_robot_mjcf/asset/base_link.STL" />
      </geometry>
    </collision>
  </link>
  <link
    name="UP1">
    <inertial>
      <origin xyz="-0.04 -0.02 0.40" rpy="0 0 0"/>
      <mass value="1089.36"/>
      <inertia
        ixx="227.88"
        ixy="10.57"
        ixz="45.05"
        iyy="276.45"
        iyz="-2.97"
        izz="190.53"/>
    </inertial>
    <visual>
      <origin
        xyz="0 0 0"
        rpy="0 0 0" />
      <geometry>
        <mesh
          filename="package://forestry_robot_mjcf/asset/UP1.STL" />
      </geometry>
      <material
        name="">
        <color
          rgba="0.65098 0.61961 0.58824 1" />
      </material>
    </visual>
    <collision>
      <origin
        xyz="0 0 0"
        rpy="0 0 0" />
      <geometry>
        <mesh
          filename="package://forestry_robot_mjcf/asset/UP1.STL" />
      </geometry>
    </collision>
  </link>
  <joint
    name="UPJ1"
    type="continuous">
    <origin
      xyz="0.370195054411909 0.0020001696392424 0.345303190455213"
      rpy="0 0 0" />
    <parent
      link="base_link" />
    <child
      link="UP1" />
    <axis
      xyz="0 0 1" />
    <limit
      lower="0"
      upper="0"
      effort="0"
      velocity="1" />
  </joint>
  <link
    name="UP2">
    <inertial>
      <origin xyz="1.96228 -0.0530702 0.000513502" rpy="0 0 0"/>
      <mass value="546.98"/>
      <inertia
        ixx="18.18"
        ixy="2.67"
        ixz="-0.04"
        iyy="737.39"
        iyz="-0.00"
        izz="739.06"/>
    </inertial>
    <visual>
      <origin
        xyz="0 0 0"
        rpy="0 0 0" />
      <geometry>
        <mesh
          filename="package://forestry_robot_mjcf/asset/UP2.STL" />
      </geometry>
      <material
        name="">
        <color
          rgba="0.792156862745098 0.819607843137255 0.933333333333333 1" />
      </material>
    </visual>
    <collision>
      <origin
        xyz="0 0 0"
        rpy="0 0 0" />
      <geometry>
        <mesh
          filename="package://forestry_robot_mjcf/asset/UP2.STL" />
      </geometry>
    </collision>
  </link>
  <joint
    name="UPJ2"
    type="revolute">
    <origin
      xyz="-0.35 0.006485 1.402"
      rpy="1.5707963267949 0 0" />
    <parent
      link="UP1" />
    <child
      link="UP2" />
    <axis
      xyz="0 0 1" />
    <limit
      lower="0"
      upper="1.05"
      effort="0"
      velocity="0.5" />
  </joint>
  <link
    name="UP3">
    <inertial>
      <origin xyz="1.36179 -0.0333441 -0.000208761" rpy="0 0 0"/>
      <mass value="329.692"/>
      <inertia
        ixx="7.73"
        ixy="-3.61"
        ixz="0.37"
        iyy="333.48"
        iyz="-0.04"
        izz="335.12"/>
    </inertial>
    <visual>
      <origin
        xyz="0 0 0"
        rpy="0 0 0" />
      <geometry>
        <mesh
          filename="package://forestry_robot_mjcf/asset/UP3.STL" />
      </geometry>
      <material
        name="">
        <color
          rgba="0.650980392156863 0.619607843137255 0.588235294117647 1" />
      </material>
    </visual>
    <collision>
      <origin
        xyz="0 0 0"
        rpy="0 0 0" />
      <geometry>
        <mesh
          filename="package://forestry_robot_mjcf/asset/UP3.STL" />
      </geometry>
    </collision>
  </link>
  <joint
    name="UPJ3"
    type="revolute">
    <origin
      xyz="4 -0.0650000000000002 0.00192735026919154"
      rpy="0 0 0" />
    <parent
      link="UP2" />
    <child
      link="UP3" />
    <axis
      xyz="0 0 1" />
    <limit
      lower="-2.01"
      upper="0"
      effort="0"
      velocity="0.5" />
  </joint>
  <link
    name="UP4">
    <inertial>
      <origin xyz="0.000424178 -0.0051871 1.65538" rpy="0 0 0"/>
      <mass value="195.721"/>
      <inertia
        ixx="200.76"
        ixy="-0.00"
        ixz="-0.12"
        iyy="200.20"
        iyz="1.47"
        izz="2.85"/>
    </inertial>
    <visual>
      <origin
        xyz="0 0 0"
        rpy="0 0 0" />
      <geometry>
        <mesh
          filename="package://forestry_robot_mjcf/asset/UP4.STL" />
      </geometry>
      <material
        name="">
        <color
          rgba="0.650980392156863 0.619607843137255 0.588235294117647 1" />
      </material>
    </visual>
    <collision>
      <origin
        xyz="0 0 0"
        rpy="0 0 0" />
      <geometry>
        <mesh
          filename="package://forestry_robot_mjcf/asset/UP4.STL" />
      </geometry>
    </collision>
  </link>
  <joint
    name="UPJ4"
    type="prismatic">
    <origin
      xyz="0.199999999999998 -0.0200000000000005 -0.000942350269189911"
      rpy="0 1.5707963267949 0" />
    <parent
      link="UP3" />
    <child
      link="UP4" />
    <axis
      xyz="0 0 1" />
    <limit
      lower="0"
      upper="1.65"
      effort="0"
      velocity="0.5" />
  </joint>
  <link
    name="UP5">
    <inertial>
      <origin xyz="-0.00652049 0.0924987 0.00226761" rpy="0 0 0"/>
      <mass value="13.9597"/>
      <inertia
        ixx="0.07"
        ixy="-0.00"
        ixz="-0.00"
        iyy="0.03"
        iyz="0.01"
        izz="0.08"/>
    </inertial>
    <visual>
      <origin
        xyz="0 0 0"
        rpy="0 0 0" />
      <geometry>
        <mesh
          filename="package://forestry_robot_mjcf/asset/UP5.STL" />
      </geometry>
      <material
        name="">
        <color
          rgba="0.650980392156863 0.619607843137255 0.588235294117647 1" />
      </material>
    </visual>
    <collision>
      <origin
        xyz="0 0 0"
        rpy="0 0 0" />
      <geometry>
        <mesh
          filename="package://forestry_robot_mjcf/asset/UP5.STL" />
      </geometry>
    </collision>
  </link>
  <joint
    name="UPJ5"
    type="revolute">
    <origin
      xyz="-0.00226999999999946 -0.0658088570286148 3.158"
      rpy="3.14159265358979 1.5707963267949 0" />
    <parent
      link="UP4" />
    <child
      link="UP5" />
    <axis
      xyz="0 0 1" />
    <limit
      lower="-1.571"
      upper="3.14159265358979"
      effort="0"
      velocity="1" />
  </joint>
  <link
    name="UP6">
    <inertial>
      <origin xyz="-5.85809e-11 0.173367 0.0" rpy="0 0 0"/>
      <mass value="71.3673"/>
      <inertia
        ixx="0.74"
        ixy="0.00"
        ixz="0.00"
        iyy="0.38"
        iyz="0.00"
        izz="0.72"/>
    </inertial>
    <visual>
      <origin
        xyz="0 0 0"
        rpy="0 0 0" />
      <geometry>
        <mesh
          filename="package://forestry_robot_mjcf/asset/UP6.STL" />
      </geometry>
      <material
        name="">
        <color
          rgba="0.650980392156863 0.619607843137255 0.588235294117647 1" />
      </material>
    </visual>
    <collision>
      <origin
        xyz="0 0 0"
        rpy="0 0 0" />
      <geometry>
        <mesh
          filename="package://forestry_robot_mjcf/asset/UP6.STL" />
      </geometry>
    </collision>
  </link>
  <joint
    name="UPJ6"
    type="revolute">
    <origin
      xyz="0 0.160000000000002 -0.00227000000000289"
      rpy="0 -1.5707963267949 0" />
    <parent
      link="UP5" />
    <child
      link="UP6" />
    <axis
      xyz="0 0 1" />
    <limit
      lower="-1.571"
      upper="1.571"
      effort="0"
      velocity="1" />
  </joint>
  <link
    name="TOOL1">
    <inertial>
      <origin xyz="-0.228346 0.00102534 -0.336559" rpy="0 0 0"/>
      <mass value="467.87"/>
      <inertia
        ixx="39.19"
        ixy="-0.35"
        ixz="-2.74"
        iyy="51.82"
        iyz="-0.21"
        izz="53.3"/>
    </inertial>
    <visual>
      <origin
        xyz="0 0 0"
        rpy="0 0 0" />
      <geometry>
        <mesh
          filename="package://forestry_robot_mjcf/asset/TOOL1.STL" />
      </geometry>
      <material
        name="">
        <color
          rgba="0.650980392156863 0.619607843137255 0.588235294117647 1" />
      </material>
    </visual>
    <collision>
      <origin
        xyz="0 0 0"
        rpy="0 0 0" />
      <geometry>
        <mesh
          filename="package://forestry_robot_mjcf/asset/TOOL1.STL" />
      </geometry>
    </collision>
  </link>
  <joint
    name="TOOLJ1"
    type="revolute">
    <origin
      xyz="0 0.342999999999996 0"
      rpy="1.5707963267949 1.5707963267949 0" />
    <parent
      link="UP6" />
    <child
      link="TOOL1" />
    <axis
      xyz="0 0 1" />
    <limit
      lower="0"
      upper="0"
      effort="0"
      velocity="0" />
  </joint>
</robot>