<mujoco model="ecvt_v2">
  <compiler angle="radian" meshdir="../asset"/>

  <asset>
    <mesh name="base_link" file="base_link.STL"/>
    <mesh name="FR1" file="FR1.STL"/>
    <mesh name="FR2" file="FR2.STL"/>
    <mesh name="FR3" file="FR3.STL"/>
    <mesh name="FRD4" file="FRD4.STL"/>
    <mesh name="FR4" file="FR4.STL"/>
    <mesh name="FR5" file="FR5.STL"/>
    <mesh name="FRW" file="FRW.STL"/>
    <mesh name="FRD12" file="FRD12.STL"/>
    <mesh name="FRD02" file="FRD02.STL"/>
    <mesh name="FRD2" file="FRD2.STL"/>
    <mesh name="FRD1" file="FRD1.STL"/>
    <mesh name="FL1" file="FL1.STL"/>
    <mesh name="FL2" file="FL2.STL"/>
    <mesh name="FL3" file="FL3.STL"/>
    <mesh name="FLD4" file="FLD4.STL"/>
    <mesh name="FL4" file="FL4.STL"/>
    <mesh name="FL5" file="FL5.STL"/>
    <mesh name="FLW" file="FLW.STL"/>
    <mesh name="FLD12" file="FLD12.STL"/>
    <mesh name="FLD02" file="FLD02.STL"/>
    <mesh name="FLD2" file="FLD2.STL"/>
    <mesh name="FLD1" file="FLD1.STL"/>
    <mesh name="RL1" file="RL1.STL"/>
    <mesh name="RL2" file="RL2.STL"/>
    <mesh name="RL3" file="RL3.STL"/>
    <mesh name="RLD4" file="RLD4.STL"/>
    <mesh name="RL4" file="RL4.STL"/>
    <mesh name="RL5" file="RL5.STL"/>
    <mesh name="RLW" file="RLW.STL"/>
    <mesh name="RLD12" file="RLD12.STL"/>
    <mesh name="RLD02" file="RLD02.STL"/>
    <mesh name="RLD2" file="RLD2.STL"/>
    <mesh name="RLD1" file="RLD1.STL"/>
    <mesh name="RR1" file="RR1.STL"/>
    <mesh name="RR2" file="RR2.STL"/>
    <mesh name="RR3" file="RR3.STL"/>
    <mesh name="RRD4" file="RRD4.STL"/>
    <mesh name="RR4" file="RR4.STL"/>
    <mesh name="RR5" file="RR5.STL"/>
    <mesh name="RRW" file="RRW.STL"/>
    <mesh name="RRD12" file="RRD12.STL"/>
    <mesh name="RRD02" file="RRD02.STL"/>
    <mesh name="RRD2" file="RRD2.STL"/>
    <mesh name="RRD1" file="RRD1.STL"/>
    <mesh name="UP1" file="UP1.STL"/>
    <mesh name="UP2" file="UP2.STL"/>
    <mesh name="UP3" file="UP3.STL"/>
    <mesh name="UP4" file="UP4.STL"/>
    <mesh name="UP5" file="UP5.STL"/>
    <mesh name="UP6" file="UP6.STL"/>
    <mesh name="TOOL1" file="TOOL1.STL"/>
  </asset>

  <worldbody>
    <body name="base_link" pos="0 0 2.4">
      <inertial pos="-0.15979 0.0032587 0.016482"  mass="5233.5858073096" fullinertia="922.83227588664 979.828076421376 1749.10791681459 0.004429 -0.33231 -0.29594"/>
      <geom type="mesh" rgba="0.65098 0.61961 0.58824 1" mesh="base_link" contype="0"/>
      <site name="imu_in_base" pos="0 0.002 0" size="0.1" rgba="1 0 1 1"/>
      <body name="UP1" pos="0.370195 0.00200017 0.345303">
        <inertial pos="-0.15979 0.0032587 0.016482" quat="-0.000109313 0.706965 -0.000162725 0.707249" mass="5233.6" diaginertia="1749.1 979.83 922.83"/>
        <joint name="UPJ1" pos="0 0 0" axis="0 0 1" frictionloss="50" damping="10"/>
        <geom type="mesh" rgba="0.65098 0.61961 0.58824 1" mesh="UP1" contype="0"/>
        <body name="UP2" pos="-0.35 0.006485 1.402" quat="0.707107 0.707107 0 0">
          <inertial pos="1.96228 -0.0530702 0.000513502" quat="0.000542377 0.707107 -0.000279679 0.707107" mass="69.679" diaginertia="59.4322 59.1755 0.652361"/>
          <joint name="UPJ2" pos="0 0 0" axis="0 0 1" range="0 1.0472" frictionloss="50" damping="10"/>
          <geom type="mesh" rgba="0.792157 0.819608 0.933333 1" mesh="UP2" contype="0"/>
          <body name="UP3" pos="4 -0.065 0.00192735">
            <inertial pos="1.36179 -0.0333441 -0.000208761" quat="0.500582 0.500584 0.499417 0.499415" mass="329.692" diaginertia="187.712 186.602 3.5703"/>
            <joint name="UPJ3" pos="0 0 0" axis="0 0 1" range="-2.0106193 0" frictionloss="50" damping="10"/>
            <geom type="mesh" rgba="0.65098 0.619608 0.588235 1" mesh="UP3" contype="0"/>
            <body name="UP4" pos="0.2 -0.02 -0.00094235" quat="0.707107 0 0.707107 0">
              <inertial pos="0.000424178 -0.0051871 1.65538" quat="0.707107 7.44659e-05 -7.44659e-05 0.707107" mass="195.721" diaginertia="106.593 106.033 1.36368"/>
              <joint name="UPJ4" pos="0 0 0" axis="0 0 1" type="slide" range="0 1.65" frictionloss="50" damping="10"/>
              <geom type="mesh" rgba="0.65098 0.619608 0.588235 1" mesh="UP4" contype="0"/>
              <body name="UP5" pos="-0.00227 -0.0658089 3.158" quat="0 0.707107 0 -0.707107">
                <inertial pos="-0.00652049 0.0924987 0.00226761" quat="0.524167 0.517362 -0.481926 0.474693" mass="13.9597" diaginertia="0.0484452 0.045585 0.0207449"/>
                <joint name="UPJ5" pos="0 0 0" axis="0 0 1" range="-1.571 3.14159265358979" frictionloss="300" damping="50"/>
                <geom type="mesh" rgba="0.65098 0.619608 0.588235 1" mesh="UP5" contype="0"/>
                <body name="UP6" pos="0 0.16 -0.00227" quat="0.707107 0 -0.707107 0">
                  <inertial pos="-5.85809e-11 0.173367 0" quat="0.707107 0.707107 0 0" mass="71.3673" diaginertia="0.743252 0.716572 0.377291"/>
                  <joint name="UPJ6" pos="0 0 0" axis="0 0 1" range="-1.571 1.571" frictionloss="300" damping="50"/>
                  <geom type="mesh" rgba="0.65098 0.619608 0.588235 1" mesh="UP6" contype="0"/>
                  <body name="TOOL1" pos="0 0.343 0" quat="0.5 0.5 0.5 -0.5">
                    <inertial pos="-0.228346 0.00102534 -0.336559" quat="0.998425 -0.00505242 0.0520484 -0.0203296" mass="467.87" diaginertia="11.3225 8.46509 6.95886"/>
                    <joint name="TOOLJ1" pos="0 0 0" axis="0 0 1" frictionloss="50" damping="10"/>
                    <geom type="mesh" rgba="0.65098 0.619608 0.588235 1" mesh="TOOL1" contype="0"/>
                  </body>
                </body>
              </body>
            </body>
          </body>
        </body>
      </body>
    </body>
  </worldbody>

  <actuator>
    <motor name="UPJ1_act" joint="UPJ1" gear="1" />
    <motor name="UPJ2_act" joint="UPJ2" gear="1" />
    <motor name="UPJ3_act" joint="UPJ3" gear="1" />
    <motor name="UPJ4_act" joint="UPJ4" gear="1" />
    <motor name="TOOLJ1_act" joint="TOOLJ1" gear="1" />
  </actuator>

  <sensor>
    <jointpos name="UPJ1_pos" joint="UPJ1" />
    <jointpos name="UPJ2_pos" joint="UPJ2" />
    <jointpos name="UPJ3_pos" joint="UPJ3" />
    <jointpos name="UPJ4_pos" joint="UPJ4" />
    <jointpos name="UPJ5_pos" joint="UPJ5" />
    <jointpos name="UPJ6_pos" joint="UPJ6" />
    <jointpos name="TOOLJ1_pos" joint="TOOLJ1" />

    <jointvel name="UPJ1_vel" joint="UPJ1" />
    <jointvel name="UPJ2_vel" joint="UPJ2" />
    <jointvel name="UPJ3_vel" joint="UPJ3" />
    <jointvel name="UPJ4_vel" joint="UPJ4" />
    <jointvel name="UPJ5_vel" joint="UPJ5" />
    <jointvel name="UPJ6_vel" joint="UPJ6" />
    <jointvel name="TOOLJ1_vel" joint="TOOLJ1" />

    <framequat name="base_quat" objtype="site" objname="imu_in_base" />
    <gyro name="base_gyro" site="imu_in_base" />
    <accelerometer name="base_acc" site="imu_in_base" />

    <framepos name="frame_pos" objtype="site" objname="imu_in_base" />
    <framelinvel name="frame_vel" objtype="site" objname="imu_in_base" />
  </sensor>

</mujoco>
