<mujoco model="simple_model_for_urdf.SLDASM">
  <compiler angle="radian" meshdir="meshes/modified"/>

  <asset>
    <mesh name="base_link" content_type="model/stl" file="base_link.STL"/>
    <mesh name="FR1" content_type="model/stl" file="FR1.STL"/>
    <mesh name="FR2" content_type="model/stl" file="FR2.STL"/>
    <mesh name="FR3" content_type="model/stl" file="FR3.STL"/>
    <mesh name="FRD4" content_type="model/stl" file="FRD4.STL"/>
    <mesh name="FR4" content_type="model/stl" file="FR4.STL"/>
    <mesh name="FR5" content_type="model/stl" file="FR5.STL"/>
    <mesh name="FRW" content_type="model/stl" file="FRW.STL"/>
    <mesh name="FRD12" content_type="model/stl" file="FRD12.STL"/>
    <mesh name="FRD02" content_type="model/stl" file="FRD02.STL"/>
    <mesh name="FRD2" content_type="model/stl" file="FRD2.STL"/>
    <mesh name="FRD1" content_type="model/stl" file="FRD1.STL"/>
    <mesh name="FL1" content_type="model/stl" file="FL1.STL"/>
    <mesh name="FL2" content_type="model/stl" file="FL2.STL"/>
    <mesh name="FL3" content_type="model/stl" file="FL3.STL"/>
    <mesh name="FLD4" content_type="model/stl" file="FLD4.STL"/>
    <mesh name="FL4" content_type="model/stl" file="FL4.STL"/>
    <mesh name="FL5" content_type="model/stl" file="FL5.STL"/>
    <mesh name="FLW" content_type="model/stl" file="FLW.STL"/>
    <mesh name="FLD12" content_type="model/stl" file="FLD12.STL"/>
    <mesh name="FLD02" content_type="model/stl" file="FLD02.STL"/>
    <mesh name="FLD2" content_type="model/stl" file="FLD2.STL"/>
    <mesh name="FLD1" content_type="model/stl" file="FLD1.STL"/>
    <mesh name="RL1" content_type="model/stl" file="RL1.STL"/>
    <mesh name="RL2" content_type="model/stl" file="RL2.STL"/>
    <mesh name="RL3" content_type="model/stl" file="RL3.STL"/>
    <mesh name="RLD4" content_type="model/stl" file="RLD4.STL"/>
    <mesh name="RL4" content_type="model/stl" file="RL4.STL"/>
    <mesh name="RL5" content_type="model/stl" file="RL5.STL"/>
    <mesh name="RLW" content_type="model/stl" file="RLW.STL"/>
    <mesh name="RLD12" content_type="model/stl" file="RLD12.STL"/>
    <mesh name="RLD02" content_type="model/stl" file="RLD02.STL"/>
    <mesh name="RLD2" content_type="model/stl" file="RLD2.STL"/>
    <mesh name="RLD1" content_type="model/stl" file="RLD1.STL"/>
    <mesh name="RR1" content_type="model/stl" file="RR1.STL"/>
    <mesh name="RR2" content_type="model/stl" file="RR2.STL"/>
    <mesh name="RR3" content_type="model/stl" file="RR3.STL"/>
    <mesh name="RRD4" content_type="model/stl" file="RRD4.STL"/>
    <mesh name="RR4" content_type="model/stl" file="RR4.STL"/>
    <mesh name="RR5" content_type="model/stl" file="RR5.STL"/>
    <mesh name="RRW" content_type="model/stl" file="RRW.STL"/>
    <mesh name="RRD12" content_type="model/stl" file="RRD12.STL"/>
    <mesh name="RRD02" content_type="model/stl" file="RRD02.STL"/>
    <mesh name="RRD2" content_type="model/stl" file="RRD2.STL"/>
    <mesh name="RRD1" content_type="model/stl" file="RRD1.STL"/>
    <mesh name="UP1" content_type="model/stl" file="UP1.STL"/>
    <mesh name="UP2" content_type="model/stl" file="UP2.STL"/>
    <mesh name="UP3" content_type="model/stl" file="UP3.STL"/>
    <mesh name="UP4" content_type="model/stl" file="UP4.STL"/>
    <mesh name="UP5" content_type="model/stl" file="UP5.STL"/>
    <mesh name="UP6" content_type="model/stl" file="UP6.STL"/>
    <mesh name="TOOL1" content_type="model/stl" file="TOOL1.STL"/>
  </asset>

  <worldbody>
    <body name="base_link" pos="0 0 2.4">
      <inertial pos="0.159789321065817 -0.00325874078575712 0.0164823311093963" quat="1 0 0 0" mass="5233.5858073096" diaginertia="922.83227588664 979.828076421376 1749.10791681459"/>
      <geom type="mesh" rgba="0.65098 0.619608 0.588235 1" mesh="base_link" contype="0"/>
      <freejoint />
      <site name="imu_in_base" pos="0 0 0" size="0.1" rgba="1 0 1 1"/>
      <body name="FR1" pos="-1.2832 0.9105 -0.180697" quat="0 0 0 1">
        <inertial pos="0.152686 0.0133901 0.0152396" quat="0.389075 0.357969 -0.634032 0.564343" mass="195.801" diaginertia="9.41881 8.87133 6.01684"/>
        <joint name="FRJ1" pos="0 0 0" axis="0 0 1" range="-0.855386 0.504226" frictionloss="50" damping="10"/>
        <geom type="mesh" rgba="0.65098 0.619608 0.588235 1" mesh="FR1" contype="0"/>
        <body name="FR2" pos="0.337 0 -0.085" quat="0.707107 0.707107 0 0">
          <inertial pos="0.721598 0.0715238 0.00726563" quat="0.495737 0.496675 0.508922 0.498556" mass="369.433" diaginertia="39.8309 38.9704 4.71746"/>
          <joint name="FRJ2" pos="0 0 0" axis="0 0 1" range="-1.019272 0.9930923" frictionloss="50" damping="10"/>
          <geom type="mesh" rgba="0.65098 0.619608 0.588235 1" mesh="FR2" contype="0"/>
          <body name="FR3" pos="1.4 0 0">
            <inertial pos="0.0088445 -0.403849 0.0202592" quat="0.701166 0.712951 -0.00686285 -0.00461185" mass="206.927" diaginertia="16.5446 15.3501 1.88701"/>
            <joint name="FRJ3" pos="0 0 0" axis="0 0 1" range="-0.9756391 0.9826204" frictionloss="50" damping="10"/>
            <geom type="mesh" rgba="0.65098 0.619608 0.588235 1" mesh="FR3" contype="0"/>
            <body name="FRD4" pos="0 -1 0">
              <inertial pos="3.37244e-09 -1.60239e-08 -0.250941" quat="0.5 0.5 -0.5 0.5" mass="0.0484065" diaginertia="5.84343e-05 3.11595e-05 3.11595e-05"/>
              <!-- <joint name="FRDJ4" pos="0 0 0" axis="0 0 1" range="-1.571 1.571"/> -->
              <geom type="mesh" rgba="0.756863 0.768627 0.752941 1" mesh="FRD4" contype="0"/>
              <body name="FR4">
                <inertial pos="0.0063312 -0.161878 -0.0100517" quat="0.692583 -0.000709633 -0.00577805 0.721314" mass="187.865" diaginertia="8.24066 5.04865 4.00673"/>
                <joint name="FRJ4" pos="0 0 0" axis="0 0 1" range="-3.14159 3.14159" frictionloss="50" damping="10"/>
                <geom type="mesh" rgba="0.65098 0.619608 0.588235 1" mesh="FR4" contype="0"/>
                <body name="FR5" pos="0.015 -0.288 0" quat="0.707107 -0.707107 0 0">
                  <inertial pos="-8.15523e-10 -0.417284 -0.16155" quat="0.492752 0.507145 -0.50715 0.492746" mass="326.115" diaginertia="17.0397 14.1814 8.7745"/>
                  <joint name="FRJ5" pos="0 0 0" axis="0 0 1" range="-3.14159 3.14159" frictionloss="50" damping="10"/>
                  <geom type="mesh" rgba="0.65098 0.619608 0.588235 1" mesh="FR5" contype="0"/>
                  <body name="FRW" pos="0 -0.66506 -0.171" quat="0 0 0.707107 0.707107">
                    <inertial pos="0 0 2.84916e-06" quat="0.5 0.5 -0.5 0.5" mass="475.924" diaginertia="129.608 72.7914 72.7914"/>
                    <joint name="FRJW" pos="0 0 0" axis="0 0 -1" frictionloss="10000000" damping="10"/>
                    <geom type="mesh" rgba="0.792157 0.819608 0.933333 1" mesh="FRW" contype="0" conaffinity="0"/>
                    <flexcomp name="FR_tire" type="cylinder" rigid="true"
                            pos="0 0 0"
                            count="5 5 5"
                            spacing="0.3329125 0.3329125 0.115"
                            euler="0 0 0"
                            radius="0.01" dim="3"
                            rgba="1 1 1 0" group="5"
                            mass="436.42578487557">
                      <contact internal="false" selfcollide="none" contype="0"/>
                       <edge equality="true" solref="0.01 1.5" solimp="0.9 0.95 0.001"/>
                    </flexcomp>
                  </body>
                </body>
              </body>
            </body>
          </body>
          <body name="FRD12" pos="1.4 0 0" quat="0.707107 0 0 -0.707107">
            <inertial pos="-0.0386747 0.0386747 0.010841" quat="0.923478 -0.0112776 -0.0272266 -0.382517" mass="45.6419" diaginertia="0.967455 0.835977 0.407678"/>
            <joint name="FRDJ12" pos="0 0 0" axis="0 0 1" range="-3.14159 3.14159" frictionloss="50" damping="10"/>
            <geom type="mesh" rgba="0.65098 0.619608 0.588235 1" mesh="FRD12" contype="0"/>
            <body name="FRD02" pos="0 0.21 0">
              <inertial pos="-9.74909e-12 -1.99307e-12 0.246232" quat="0.5 0.5 -0.5 0.5" mass="0.00902948" diaginertia="4.17725e-06 2.13279e-06 2.13279e-06"/>
              <!-- <joint name="FRDJ02" pos="0 0 0" axis="0 0 1" range="-1.571 1.571"/> -->
              <geom type="mesh" rgba="0.792157 0.819608 0.933333 1" mesh="FRD02" contype="0"/>
              <body name="FRD2">
                <inertial pos="0.511714 0.0219456 -0.000357629" quat="0.5 0.5 0.5 0.5" mass="48.8027" diaginertia="3.43904 3.02264 0.470038"/>
                <joint name="FRDJ2" pos="0 0 0" axis="0 0 1" range="-3.14159 3.14159" frictionloss="50" damping="10"/>
                <geom type="mesh" rgba="0.65098 0.619608 0.588235 1" mesh="FRD2" contype="0"/>
              </body>
            </body>
          </body>
        </body>
        <body name="FRD1" pos="0.337 0 0.125" quat="0.707107 0.707107 0 0">
          <inertial pos="0.697879 0 0.000844984" quat="0 0.707107 0 0.707107" mass="50.3138" diaginertia="7.99149 7.96246 0.0331657"/>
          <joint name="FRDJ1" pos="0 0 0" axis="0 0 1" range="-3.14159 3.14159" frictionloss="50" damping="10"/>
          <geom type="mesh" rgba="0.65098 0.619608 0.588235 1" mesh="FRD1" contype="0"/>
        </body>
      </body>
      <body name="FL1" pos="-1.2832 -0.9145 -0.180697" quat="0 0 0 1">
        <inertial pos="0.152686 0.0133901 0.0152396" quat="0.389075 0.357969 -0.634032 0.564343" mass="195.801" diaginertia="9.41881 8.87133 6.01684"/>
        <joint name="FLJ1" pos="0 0 0" axis="0 0 1" range="-0.504226 0.855386" frictionloss="50" damping="10"/>
        <geom type="mesh" rgba="0.65098 0.619608 0.588235 1" mesh="FL1" contype="0"/>
        <body name="FL2" pos="0.337 0 -0.085" quat="0.707107 0.707107 0 0">
          <inertial pos="0.721598 0.0715238 0.00726563" quat="0.495737 0.496675 0.508922 0.498556" mass="369.433" diaginertia="39.8309 38.9704 4.71746"/>
          <joint name="FLJ2" pos="0 0 0" axis="0 0 1" range="-1.019272 0.9930923" frictionloss="50" damping="10"/>
          <geom type="mesh" rgba="0.65098 0.619608 0.588235 1" mesh="FL2" contype="0"/>
          <body name="FL3" pos="1.4 0 0" quat="0.707107 0 0 -0.707107">
            <inertial pos="0.403849 0.0088445 0.0202592" quat="0.49906 0.508985 0.499279 0.492538" mass="206.927" diaginertia="16.5446 15.3501 1.88701"/>
            <joint name="FLJ3" pos="0 0 0" axis="0 0 1" range="-0.9756391 0.9826204" frictionloss="50" damping="10"/>
            <geom type="mesh" rgba="0.65098 0.619608 0.588235 1" mesh="FL3" contype="0"/>
            <body name="FLD4" pos="1 0 0" quat="0.707107 0 0 0.707107">
              <inertial pos="3.23499e-09 -1.60523e-08 -0.250941" quat="0.5 0.5 -0.5 0.5" mass="0.0484065" diaginertia="5.84343e-05 3.11595e-05 3.11595e-05"/>
              <!-- <joint name="FLDJ4" pos="0 0 0" axis="0 0 1" range="-1.571 1.571"/> -->
              <geom type="mesh" rgba="0.756863 0.768627 0.752941 1" mesh="FLD4" contype="0"/>
              <body name="FL4">
                <inertial pos="0.0063312 -0.161878 -0.0100517" quat="0.692583 -0.000709633 -0.00577805 0.721314" mass="187.865" diaginertia="8.24066 5.04865 4.00673"/>
                <joint name="FLJ4" pos="0 0 0" axis="0 0 1" range="-3.14159 3.14159" frictionloss="50" damping="10"/>
                <geom type="mesh" rgba="0.65098 0.619608 0.588235 1" mesh="FL4" contype="0"/>
                <body name="FL5" pos="0.015 -0.288 0" quat="0.707107 -0.707107 0 0">
                  <inertial pos="8.15524e-10 0.417284 -0.16155" quat="0.50715 0.492746 -0.492752 0.507145" mass="326.115" diaginertia="17.0397 14.1814 8.7745"/>
                  <joint name="FLJ5" pos="0 0 0" axis="0 0 1" range="-3.14159 3.14159" frictionloss="50" damping="10"/>
                  <geom type="mesh" rgba="0.65098 0.619608 0.588235 1" mesh="FL5" contype="0"/>
                  <body name="FLW" pos="0 0.66506 -0.171" quat="0 0 0.707107 0.707107">
                    <inertial pos="0 0 -2.84916e-06" quat="0.5 0.5 -0.5 0.5" mass="475.924" diaginertia="129.608 72.7914 72.7914"/>
                    <joint name="FLJW" pos="0 0 0" axis="0 0 1" frictionloss="10000000" damping="10"/>
                    <geom type="mesh" rgba="0.792157 0.819608 0.933333 1" mesh="FLW" contype="0" conaffinity="0"/>
                    <flexcomp name="FL_tire" type="cylinder" rigid="true"
                            pos="0 0 0"
                            count="5 5 5"
                            spacing="0.3329125 0.3329125 0.115"
                            euler="0 0 0"
                            radius="0.01" dim="3"
                            rgba="1 1 1 0" group="5"
                            mass="436.42578487557">
                      <contact internal="false" selfcollide="none" contype="0"/>
                       <edge equality="true" solref="0.01 1.5" solimp="0.9 0.95 0.001"/>
                    </flexcomp>
                  </body>
                </body>
              </body>
            </body>
          </body>
          <body name="FLD12" pos="1.4 0 0">
            <inertial pos="0.0386747 0.0386747 0.010841" quat="0.923478 -0.0112776 0.0272266 0.382517" mass="45.6419" diaginertia="0.967455 0.835977 0.407678"/>
            <joint name="FLDJ12" pos="0 0 0" axis="0 0 1" range="-3.14159 3.14159" frictionloss="50" damping="10"/>
            <geom type="mesh" rgba="0.65098 0.619608 0.588235 1" mesh="FLD12" contype="0"/>
            <body name="FLD02" pos="0.21 0 0">
              <inertial pos="-1.98908e-12 9.74437e-12 0.246232" quat="0.5 0.5 -0.5 0.5" mass="0.00902948" diaginertia="4.17725e-06 2.13279e-06 2.13279e-06"/>
              <!-- <joint name="FLDJ02" pos="0 0 0" axis="0 0 1" range="-1.571 1.571"/> -->
              <geom type="mesh" rgba="0.792157 0.819608 0.933333 1" mesh="FLD02" contype="0"/>
              <body name="FLD2">
                <inertial pos="0.0219456 -0.511714 -0.000357629" quat="0.707107 0.707107 0 0" mass="48.8027" diaginertia="3.43904 3.02264 0.470038"/>
                <joint name="FLDJ2" pos="0 0 0" axis="0 0 1" range="-3.14159 3.14159" frictionloss="50" damping="10"/>
                <geom type="mesh" rgba="0.65098 0.619608 0.588235 1" mesh="FLD2" contype="0"/>
              </body>
            </body>
          </body>
        </body>
        <body name="FLD1" pos="0.337 0 0.125" quat="0.707107 0.707107 0 0">
          <inertial pos="0.697879 0 0.000844984" quat="0 0.707107 0 0.707107" mass="50.3138" diaginertia="7.99149 7.96246 0.0331657"/>
          <joint name="FLDJ1" pos="0 0 0" axis="0 0 1" range="-3.14159 3.14159" frictionloss="50" damping="10"/>
          <geom type="mesh" rgba="0.65098 0.619608 0.588235 1" mesh="FLD1" contype="0"/>
        </body>
      </body>
      <body name="RL1" pos="1.3668 -0.9145 -0.180697">
        <inertial pos="0.152686 0.0133901 0.0152396" quat="0.389075 0.357969 -0.634032 0.564343" mass="195.801" diaginertia="9.41881 8.87133 6.01684"/>
        <joint name="RLJ1" pos="0 0 0" axis="0 0 1" range="-0.855386 0.504226" frictionloss="50" damping="10"/>
        <geom type="mesh" rgba="0.65098 0.619608 0.588235 1" mesh="RL1" contype="0"/>
        <body name="RL2" pos="0.337 0 -0.085" quat="0 0 0.707107 0.707107">
          <inertial pos="-0.721598 0.0715238 -0.00726563" quat="0.498556 0.508922 0.496675 0.495737" mass="369.433" diaginertia="39.8309 38.9704 4.71746"/>
          <joint name="RLJ2" pos="0 0 0" axis="0 0 1" range="-0.9930923 1.019272" frictionloss="50" damping="10"/>
          <geom type="mesh" rgba="0.65098 0.619608 0.588235 1" mesh="RL2" contype="0"/>
          <body name="RL3" pos="-1.4 0 0">
            <inertial pos="-0.0088445 -0.403849 -0.0202592" quat="0.712951 0.701166 0.00461185 0.00686285" mass="206.927" diaginertia="16.5446 15.3501 1.88701"/>
            <joint name="RLJ3" pos="0 0 0" axis="0 0 1" range="-0.9826204 0.9756391" frictionloss="50" damping="10"/>
            <geom type="mesh" rgba="0.65098 0.619608 0.588235 1" mesh="RL3" contype="0"/>
            <body name="RLD4" pos="0 -1 0">
              <inertial pos="1.49499e-08 -6.68186e-09 0.250941" quat="0 0.707107 0 0.707107" mass="0.0484065" diaginertia="5.84343e-05 3.11595e-05 3.11595e-05"/>
              <!-- <joint name="RLDJ4" pos="0 0 0" axis="0 0 -1" range="-1.571 1.571"/> -->
              <geom type="mesh" rgba="0.756863 0.768627 0.752941 1" mesh="RLD4" contype="0"/>
              <body name="RL4">
                <inertial pos="-0.0063312 -0.161878 0.0100517" quat="0.721314 -0.00577805 -0.000709633 0.692583" mass="187.865" diaginertia="8.24066 5.04865 4.00673"/>
                <joint name="RLJ4" pos="0 0 0" axis="0 0 1" range="-3.14159 3.14159" frictionloss="50" damping="10"/>
                <geom type="mesh" rgba="0.65098 0.619608 0.588235 1" mesh="RL4" contype="0"/>
                <body name="RL5" pos="-0.015 -0.288 0" quat="0 0 0.707107 0.707107">
                  <inertial pos="-8.15523e-10 -0.417284 -0.16155" quat="0.492752 0.507145 -0.50715 0.492746" mass="326.115" diaginertia="17.0397 14.1814 8.7745"/>
                  <joint name="RLJ5" pos="0 0 0" axis="0 0 1" range="-3.14159 3.14159" frictionloss="50" damping="10"/>
                  <geom type="mesh" rgba="0.65098 0.619608 0.588235 1" mesh="RL5" contype="0"/>
                  <body name="RLW" pos="0 -0.66506 -0.171" quat="0.707107 0.707107 0 0">
                    <inertial pos="0 0 -2.84916e-06" quat="0.5 0.5 -0.5 0.5" mass="475.924" diaginertia="129.608 72.7914 72.7914"/>
                    <joint name="RLJW" pos="0 0 0" axis="0 0 1" frictionloss="10000000" damping="10"/>
                    <geom type="mesh" rgba="0.792157 0.819608 0.933333 1" mesh="RLW" contype="0" conaffinity="0"/>
                    <flexcomp name="RL_tire" type="cylinder" rigid="true"
                            pos="0 0 0"
                            count="5 5 5"
                            spacing="0.3329125 0.3329125 0.115"
                            euler="0 0 0"
                            radius="0.01" dim="3"
                            rgba="1 1 1 0" group="5"
                            mass="436.42578487557">
                      <contact internal="false" selfcollide="none" contype="0"/>
                       <edge equality="true" solref="0.01 1.5" solimp="0.9 0.95 0.001"/>
                    </flexcomp>
                  </body>
                </body>
              </body>
            </body>
          </body>
          <body name="RLD12" pos="-1.4 0 0" quat="0 0 -1 0">
            <inertial pos="0.0386747 0.0386747 0.010841" quat="0.923478 -0.0112776 0.0272266 0.382517" mass="45.6419" diaginertia="0.967455 0.835977 0.407678"/>
            <joint name="RLDJ12" pos="0 0 0" axis="0 0 1" range="-3.14159 3.14159" frictionloss="50" damping="10"/>
            <geom type="mesh" rgba="0.65098 0.619608 0.588235 1" mesh="RLD12" contype="0"/>
            <body name="RLD02" pos="0.21 0 0">
              <inertial pos="9.68825e-12 -2.18947e-12 0.246232" quat="0.5 0.5 -0.5 0.5" mass="0.00902948" diaginertia="4.17725e-06 2.13279e-06 2.13279e-06"/>
              <!-- <joint name="RLDJ02" pos="0 0 0" axis="0 0 1" range="-1.571 1.571"/> -->
              <geom type="mesh" rgba="0.792157 0.819608 0.933333 1" mesh="RLD02" contype="0"/>
              <body name="RLD2">
                <inertial pos="0.0219456 -0.511714 -0.000357629" quat="0.707107 0.707107 0 0" mass="48.8027" diaginertia="3.43904 3.02264 0.470038"/>
                <joint name="RLDJ2" pos="0 0 0" axis="0 0 1" range="-3.14159 3.14159" frictionloss="50" damping="10"/>
                <geom type="mesh" rgba="0.65098 0.619608 0.588235 1" mesh="RLD2" contype="0"/>
              </body>
            </body>
          </body>
        </body>
        <body name="RLD1" pos="0.337 0 0.125" quat="0.707107 0.707107 0 0">
          <inertial pos="0.697879 0 0.000844984" quat="0 0.707107 0 0.707107" mass="50.3138" diaginertia="7.99149 7.96246 0.0331657"/>
          <joint name="RLDJ1" pos="0 0 0" axis="0 0 -1" range="-3.14159 3.14159" frictionloss="50" damping="10"/>
          <geom type="mesh" rgba="0.65098 0.619608 0.588235 1" mesh="RLD1" contype="0"/>
        </body>
      </body>
      <body name="RR1" pos="1.3668 0.9105 -0.180697">
        <inertial pos="0.152686 0.0133901 0.0152396" quat="0.389075 0.357969 -0.634032 0.564343" mass="195.801" diaginertia="9.41881 8.87133 6.01684"/>
        <joint name="RRJ1" pos="0 0 0" axis="0 0 1" range="-0.504226 0.855386" frictionloss="50" damping="10"/>
        <geom type="mesh" rgba="0.65098 0.619608 0.588235 1" mesh="RR1" contype="0"/>
        <body name="RR2" pos="0.337 0 -0.085" quat="0.707107 -0.707107 0 0">
          <inertial pos="0.721598 -0.0715237 -0.00726563" quat="0.508922 0.498556 0.495737 0.496675" mass="369.433" diaginertia="39.8309 38.9704 4.71746"/>
          <joint name="RRJ2" pos="0 0 0" axis="0 0 1" range="-0.9930923 1.019272" frictionloss="50" damping="10"/>
          <geom type="mesh" rgba="0.65098 0.619608 0.588235 1" mesh="RR2" contype="0"/>
          <body name="RR3" pos="1.4 0 0" quat="0 0 0 -1">
            <inertial pos="-0.0088445 -0.403849 -0.0202592" quat="0.712951 0.701166 0.00461185 0.00686285" mass="206.927" diaginertia="16.5446 15.3501 1.88701"/>
            <joint name="RRJ3" pos="0 0 0" axis="0 0 1" range="-0.9826204 0.9756391" frictionloss="50" damping="10"/>
            <geom type="mesh" rgba="0.65098 0.619608 0.588235 1" mesh="RR3" contype="0"/>
            <body name="RRD4" pos="0 -1 0">
              <inertial pos="1.49499e-08 -6.6818e-09 0.250941" quat="0 0.707107 0 0.707107" mass="0.0484065" diaginertia="5.84343e-05 3.11595e-05 3.11595e-05"/>
              <!-- <joint name="RRDJ4" pos="0 0 0" axis="0 0 -1" range="-1.571 1.571"/> -->
              <geom type="mesh" rgba="0.756863 0.768627 0.752941 1" mesh="RRD4" contype="0"/>
              <body name="RR4">
                <inertial pos="-0.0063312 -0.161878 0.0100517" quat="0.721314 -0.00577805 -0.000709633 0.692583" mass="187.865" diaginertia="8.24066 5.04865 4.00673"/>
                <joint name="RRJ4" pos="0 0 0" axis="0 0 1" range="-3.14159 3.14159" frictionloss="50" damping="10"/>
                <geom type="mesh" rgba="0.65098 0.619608 0.588235 1" mesh="RR4" contype="0"/>
                <body name="RR5" pos="-0.015 -0.288 0" quat="0 0 -0.707107 -0.707107">
                  <inertial pos="8.15523e-10 0.417284 -0.16155" quat="0.50715 0.492746 -0.492752 0.507145" mass="326.115" diaginertia="17.0397 14.1814 8.7745"/>
                  <joint name="RRJ5" pos="0 0 0" axis="0 0 1" range="-3.14159 3.14159" frictionloss="50" damping="10"/>
                  <geom type="mesh" rgba="0.65098 0.619608 0.588235 1" mesh="RR5" contype="0"/>
                  <body name="RRW" pos="0 0.66506 -0.171" quat="0 0 0.707107 -0.707107">
                    <inertial pos="0 0 2.84916e-06" quat="0.5 0.5 -0.5 0.5" mass="475.924" diaginertia="129.608 72.7914 72.7914"/>
                    <joint name="RRJW" pos="0 0 0" axis="0 0 -1" frictionloss="10000000" damping="10"/>
                    <geom type="mesh" rgba="0.792157 0.819608 0.933333 1" mesh="RRW" contype="0" conaffinity="0"/>
                    <flexcomp name="RR_tire" type="cylinder" rigid="true"
                            pos="0 0 0"
                            count="5 5 5"
                            spacing="0.3329125 0.3329125 0.115"
                            euler="0 0 0"
                            radius="0.01" dim="3"
                            rgba="1 1 1 0" group="5"
                            mass="436.42578487557">
                      <contact internal="false" selfcollide="none" contype="0"/>
                       <edge equality="true" solref="0.01 1.5" solimp="0.9 0.95 0.001"/>
                    </flexcomp>
                  </body>
                </body>
              </body>
            </body>
          </body>
          <body name="RRD12" pos="1.4 0 0" quat="0 1 0 0">
            <inertial pos="0.0386747 0.0386747 0.010841" quat="0.923478 -0.0112776 0.0272266 0.382517" mass="45.6419" diaginertia="0.967455 0.835977 0.407678"/>
            <joint name="RRDJ12" pos="0 0 0" axis="0 0 1" range="-3.14159 3.14159" frictionloss="50" damping="10"/>
            <geom type="mesh" rgba="0.65098 0.619608 0.588235 1" mesh="RRD12" contype="0"/>
            <body name="RRD02" pos="0.21 0 0">
              <inertial pos="9.68203e-12 -2.15206e-12 0.246232" quat="0.5 0.5 -0.5 0.5" mass="0.00902948" diaginertia="4.17725e-06 2.13279e-06 2.13279e-06"/>
              <!-- <joint name="RRDJ02" pos="0 0 0" axis="0 0 1" range="-1.571 1.571"/> -->
              <geom type="mesh" rgba="0.792157 0.819608 0.933333 1" mesh="RRD02" contype="0"/>
              <body name="RRD2">
                <inertial pos="0.0219456 -0.511714 -0.000357629" quat="0.707107 0.707107 0 0" mass="48.8027" diaginertia="3.43904 3.02264 0.470038"/>
                <joint name="RRDJ2" pos="0 0 0" axis="0 0 1" range="-3.14159 3.14159" frictionloss="50" damping="10"/>
                <geom type="mesh" rgba="0.65098 0.619608 0.588235 1" mesh="RRD2" contype="0"/>
              </body>
            </body>
          </body>
        </body>
        <body name="RRD1" pos="0.337 0 0.125" quat="0.707107 0.707107 0 0">
          <inertial pos="0.697879 -5.01552e-08 0.000844984" quat="0 0.707107 0 0.707107" mass="50.3138" diaginertia="7.99149 7.96246 0.0331657"/>
          <joint name="RRDJ1" pos="0 0 0" axis="0 0 -1" range="-3.14159 3.14159" frictionloss="50" damping="10"/>
          <geom type="mesh" rgba="0.65098 0.619608 0.588235 1" mesh="RRD1" contype="0"/>
        </body>
      </body>
      <body name="UP1" pos="-0.370195 -0.00200017 0.345303" quat="0 0 0 1">
        <inertial pos="-0.0400754 -0.0194465 0.397557" quat="0.330981 0.624851 0.624907 0.330914" mass="1089.36" diaginertia="118.48 92.7684 56.0622"/>
        <joint name="UPJ1" pos="0 0 0" axis="0 0 1" range="-2.0 2.0" frictionloss="50" damping="10"/> <!-- 임의의 joint limit -->
        <geom type="mesh" rgba="0.65098 0.619608 0.588235 1" mesh="UP1" contype="0"/>
        <body name="UP2" pos="-0.35 0.006485 1.402" quat="0.707107 0.707107 0 0">
          <inertial pos="1.96228 -0.0530702 0.000513502" quat="0.000542377 0.707107 -0.000279679 0.707107" mass="69.679" diaginertia="59.4322 59.1755 0.652361"/>
          <joint name="UPJ2" pos="0 0 0" axis="0 0 1" range="0 1.05" frictionloss="50" damping="10"/>
          <geom type="mesh" rgba="0.792157 0.819608 0.933333 1" mesh="UP2" contype="0"/>
          <body name="UP3" pos="4 -0.065 0.00192735">
            <inertial pos="1.36179 -0.0333441 -0.000208761" quat="0.500582 0.500584 0.499417 0.499415" mass="329.692" diaginertia="187.712 186.602 3.5703"/>
            <joint name="UPJ3" pos="0 0 0" axis="0 0 1" range="-2.01 0" frictionloss="50" damping="10"/>
            <geom type="mesh" rgba="0.65098 0.619608 0.588235 1" mesh="UP3" contype="0"/>
            <body name="UP4" pos="0.2 -0.02 -0.00094235" quat="0.707107 0 0.707107 0">
              <inertial pos="0.000424178 -0.0051871 1.65538" quat="0.707107 7.44659e-05 -7.44659e-05 0.707107" mass="195.721" diaginertia="106.593 106.033 1.36368"/>
              <joint name="UPJ4" pos="0 0 0" axis="0 0 1" type="slide" range="0 1.65" frictionloss="50" damping="10"/>
              <geom type="mesh" rgba="0.65098 0.619608 0.588235 1" mesh="UP4" contype="0"/>
              <body name="UP5" pos="-0.00227 -0.0658089 3.158" quat="0 0.707107 0 -0.707107">
                <inertial pos="-0.00652049 0.0924987 0.00226761" quat="0.524167 0.517362 -0.481926 0.474693" mass="13.9597" diaginertia="0.0484452 0.045585 0.0207449"/>
                <joint name="UPJ5" pos="0 0 0" axis="0 0 1" range="-3.14159 3.14159" frictionloss="100" damping="10"/>
                <geom type="mesh" rgba="0.65098 0.619608 0.588235 1" mesh="UP5" contype="0"/>
                <body name="UP6" pos="0 0.16 -0.00227" quat="0.707107 0 -0.707107 0">
                  <inertial pos="-5.85809e-11 0.173367 0" quat="0.707107 0.707107 0 0" mass="71.3673" diaginertia="0.743252 0.716572 0.377291"/>
                  <joint name="UPJ6" pos="0 0 0" axis="0 0 1" range="-1.5708 1.5708" frictionloss="100" damping="10"/>
                  <geom type="mesh" rgba="0.65098 0.619608 0.588235 1" mesh="UP6" contype="0"/>
                  <body name="TOOL1" pos="0 0.343 0" quat="0.5 0.5 0.5 -0.5">
                    <inertial pos="-0.228346 0.00102534 -0.336559" quat="0.998425 -0.00505242 0.0520484 -0.0203296" mass="467.87" diaginertia="11.3225 8.46509 6.95886"/>
                    <joint name="TOOLJ1" pos="0 0 0" axis="0 0 1" range="-1.5708 1.5708" frictionloss="50" damping="10"/>
                    <geom type="mesh" rgba="0.65098 0.619608 0.588235 1" mesh="TOOL1" contype="0"/>
                  </body>
                </body>
              </body>
            </body>
          </body>
        </body>
      </body>
    </body>
  </worldbody>

  <equality>
    <joint joint1="FRDJ1" joint2="FRJ2" polycoef="0 1 0 0 0"/>
    <joint joint1="FLDJ1" joint2="FLJ2" polycoef="0 1 0 0 0"/>
    <joint joint1="RRDJ1" joint2="RRJ2" polycoef="0 1 0 0 0"/>
    <joint joint1="RLDJ1" joint2="RLJ2" polycoef="0 1 0 0 0"/>
  </equality>

  <tendon>
    <fixed name="FR_mimic_1" limited="true" range="-1e-9 1e-9">
        <joint joint="FRDJ12" coef="1"/>
        <joint joint="FRJ2"   coef="1"/>
    </fixed>
    <fixed name="FR_mimic_2" limited="true" range="-1e-9 1e-9">
        <joint joint="FRDJ2" coef="-1"/>
        <joint joint="FRJ2"  coef="1"/>
        <joint joint="FRJ3"  coef="1"/>
    </fixed>
    <fixed name="FR_mimic_3" limited="true" range="-1e-9 1e-9">
        <joint joint="FRJ4"  coef="1"/>
        <joint joint="FRJ2"  coef="1"/>
        <joint joint="FRJ3"  coef="1"/>
    </fixed>

    <fixed name="FL_mimic_1" limited="true" range="-1e-9 1e-9">
        <joint joint="FLDJ12" coef="1"/>
        <joint joint="FLJ2"   coef="1"/>
    </fixed>
    <fixed name="FL_mimic_2" limited="true" range="-1e-9 1e-9">
        <joint joint="FLDJ2" coef="-1"/>
        <joint joint="FLJ2"  coef="1"/>
        <joint joint="FLJ3"  coef="1"/>
    </fixed>
    <fixed name="FL_mimic_3" limited="true" range="-1e-9 1e-9">
        <joint joint="FLJ4"  coef="1"/>
        <joint joint="FLJ2"  coef="1"/>
        <joint joint="FLJ3"  coef="1"/>
    </fixed>

    <fixed name="RR_mimic_1" limited="true" range="-1e-9 1e-9">
        <joint joint="RRDJ12" coef="1"/>
        <joint joint="RRJ2"   coef="-1"/>
    </fixed>
    <fixed name="RR_mimic_2" limited="true" range="-1e-9 1e-9">
        <joint joint="RRDJ2" coef="1"/>
        <joint joint="RRJ2"  coef="1"/>
        <joint joint="RRJ3"  coef="1"/>
    </fixed>
    <fixed name="RR_mimic_3" limited="true" range="-1e-9 1e-9">
        <joint joint="RRJ4"  coef="1"/>
        <joint joint="RRJ2"  coef="1"/>
        <joint joint="RRJ3"  coef="1"/>
    </fixed>

    <fixed name="RL_mimic_1" limited="true" range="-1e-9 1e-9">
        <joint joint="RLDJ12" coef="-1"/>
        <joint joint="RLJ2"   coef="1"/>
    </fixed>
    <fixed name="RL_mimic_2" limited="true" range="-1e-9 1e-9">
        <joint joint="RLDJ2" coef="1"/>
        <joint joint="RLJ2"  coef="1"/>
        <joint joint="RLJ3"  coef="1"/>
    </fixed>
    <fixed name="RL_mimic_3" limited="true" range="-1e-9 1e-9">
        <joint joint="RLJ4"  coef="1"/>
        <joint joint="RLJ2"  coef="1"/>
        <joint joint="RLJ3"  coef="1"/>
    </fixed>
  </tendon>

  <actuator>
    <motor name="FRJ1_act" joint="FRJ1" gear="1"/>
    <motor name="FRJ2_act" joint="FRJ2" gear="1"/>
    <motor name="FRJ3_act" joint="FRJ3" gear="1"/>
    <motor name="FRJ5_act" joint="FRJ5" gear="1"/>
    <position name="FRJW_act" joint="FRJW" kp="100000000" kv="5000" ctrllimited="true" ctrlrange="-20 20" />

    <motor name="FLJ1_act" joint="FLJ1" gear="1" />
    <motor name="FLJ2_act" joint="FLJ2" gear="1" />
    <motor name="FLJ3_act" joint="FLJ3" gear="1" />
    <motor name="FLJ5_act" joint="FLJ5" gear="1" />
    <position name="FLJW_act" joint="FLJW" kp="100000000" kv="5000" ctrllimited="true" ctrlrange="-20 20" />

    <motor name="RRJ1_act" joint="RRJ1" gear="1" />
    <motor name="RRJ2_act" joint="RRJ2" gear="1" />
    <motor name="RRJ3_act" joint="RRJ3" gear="1" />
    <motor name="RRJ5_act" joint="RRJ5" gear="1" />
    <position name="RRJW_act" joint="RRJW" kp="100000000" kv="5000" ctrllimited="true" ctrlrange="-20 20" />

    <motor name="RLJ1_act" joint="RLJ1" gear="1" />
    <motor name="RLJ2_act" joint="RLJ2" gear="1" />
    <motor name="RLJ3_act" joint="RLJ3" gear="1" />
    <motor name="RLJ5_act" joint="RLJ5" gear="1" />
    <position name="RLJW_act" joint="RLJW" kp="100000000" kv="5000" ctrllimited="true" ctrlrange="-20 20" />

    <motor name="UPJ1_act" joint="UPJ1" gear="1" />
    <motor name="UPJ2_act" joint="UPJ2" gear="1" />
    <motor name="UPJ3_act" joint="UPJ3" gear="1" />
    <motor name="UPJ4_act" joint="UPJ4" gear="1" />
    <motor name="TOOLJ1_act" joint="TOOLJ1" gear="1" />
  </actuator>

  <sensor>
    <jointpos name="FRJ1_pos" joint="FRJ1" />
    <jointpos name="FRJ2_pos" joint="FRJ2" />
    <jointpos name="FRJ3_pos" joint="FRJ3" />
    <jointpos name="FRJ5_pos" joint="FRJ5" />
    <jointpos name="FRJW_pos" joint="FRJW" />
    <jointpos name="FLJ1_pos" joint="FLJ1" />
    <jointpos name="FLJ2_pos" joint="FLJ2" />
    <jointpos name="FLJ3_pos" joint="FLJ3" />
    <jointpos name="FLJ5_pos" joint="FLJ5" />
    <jointpos name="FLJW_pos" joint="FLJW" />
    <jointpos name="RRJ1_pos" joint="RRJ1" />
    <jointpos name="RRJ2_pos" joint="RRJ2" />
    <jointpos name="RRJ3_pos" joint="RRJ3" />
    <jointpos name="RRJ5_pos" joint="RRJ5" />
    <jointpos name="RRJW_pos" joint="RRJW" />
    <jointpos name="RLJ1_pos" joint="RLJ1" />
    <jointpos name="RLJ2_pos" joint="RLJ2" />
    <jointpos name="RLJ3_pos" joint="RLJ3" />
    <jointpos name="RLJ5_pos" joint="RLJ5" />
    <jointpos name="RLJW_pos" joint="RLJW" />
    <jointpos name="UPJ1_pos" joint="UPJ1" />
    <jointpos name="UPJ2_pos" joint="UPJ2" />
    <jointpos name="UPJ3_pos" joint="UPJ3" />
    <jointpos name="UPJ4_pos" joint="UPJ4" />
    <jointpos name="UPJ5_pos" joint="UPJ5" />
    <jointpos name="UPJ6_pos" joint="UPJ6" />
    <jointpos name="TOOLJ1_pos" joint="TOOLJ1" />

    <jointvel name="FRJ1_vel" joint="FRJ1" />
    <jointvel name="FRJ2_vel" joint="FRJ2" />
    <jointvel name="FRJ3_vel" joint="FRJ3" />
    <jointvel name="FRJ5_vel" joint="FRJ5" />
    <jointvel name="FRJW_vel" joint="FRJW" />
    <jointvel name="FLJ1_vel" joint="FLJ1" />
    <jointvel name="FLJ2_vel" joint="FLJ2" />
    <jointvel name="FLJ3_vel" joint="FLJ3" />
    <jointvel name="FLJ5_vel" joint="FLJ5" />
    <jointvel name="FLJW_vel" joint="FLJW" />
    <jointvel name="RRJ1_vel" joint="RRJ1" />
    <jointvel name="RRJ2_vel" joint="RRJ2" />
    <jointvel name="RRJ3_vel" joint="RRJ3" />
    <jointvel name="RRJ5_vel" joint="RRJ5" />
    <jointvel name="RRJW_vel" joint="RRJW" />
    <jointvel name="RLJ1_vel" joint="RLJ1" />
    <jointvel name="RLJ2_vel" joint="RLJ2" />
    <jointvel name="RLJ3_vel" joint="RLJ3" />
    <jointvel name="RLJ5_vel" joint="RLJ5" />
    <jointvel name="RLJW_vel" joint="RLJW" />
    <jointvel name="UPJ1_vel" joint="UPJ1" />
    <jointvel name="UPJ2_vel" joint="UPJ2" />
    <jointvel name="UPJ3_vel" joint="UPJ3" />
    <jointvel name="UPJ4_vel" joint="UPJ4" />
    <jointvel name="UPJ5_vel" joint="UPJ5" />
    <jointvel name="UPJ6_vel" joint="UPJ6" />
    <jointvel name="TOOLJ1_vel" joint="TOOLJ1" />

    <framequat name="base_quat" objtype="site" objname="imu_in_base" />
    <gyro name="base_gyro" site="imu_in_base" />
    <accelerometer name="base_acc" site="imu_in_base" />

    <framepos name="frame_pos" objtype="site" objname="imu_in_base" />
    <framelinvel name="frame_vel" objtype="site" objname="imu_in_base" />
  </sensor>

</mujoco>
